DEBUG:root:Musicurie traceback log. It starts at
DEBUG:root:2015-02-12 13:20:19
DEBUG:root:Musicurie traceback log. It starts at
DEBUG:root:2015-02-12 13:21:10
ERROR:root:Got exception on scrapAll
Traceback (most recent call last):
  File "ultimateCrawler.py", line 230, in scrapAll
    trackId = self.scrapSource(sources[s], title, artist)
TypeError: scrapSource() missing 1 required positional argument: 'album'
DEBUG:root:Musicurie traceback log. It starts at
DEBUG:root:2015-02-12 13:21:27
ERROR:root:Got exception on scrapAll
Traceback (most recent call last):
  File "ultimateCrawler.py", line 230, in scrapAll
    trackId = self.scrapSource(sources[s], title, artist)
TypeError: scrapSource() missing 1 required positional argument: 'album'
DEBUG:root:Musicurie traceback log. It starts at
DEBUG:root:2015-02-12 13:22:03
DEBUG:root:Musicurie traceback log. It starts at
DEBUG:root:2015-02-12 13:22:32
DEBUG:root:Musicurie traceback log. It starts at
DEBUG:root:2015-02-13 00:43:03
ERROR:root:Got exception on scrapMelon: 10cm-죽겠네
Traceback (most recent call last):
  File "ultimateCrawler.py", line 90, in scrapMelon
    html = f.read().decode('utf-8')
  File "/Library/Frameworks/Python.framework/Versions/3.4/lib/python3.4/http/client.py", line 506, in read
    return self._readall_chunked()
  File "/Library/Frameworks/Python.framework/Versions/3.4/lib/python3.4/http/client.py", line 592, in _readall_chunked
    value.append(self._safe_read(chunk_left))
  File "/Library/Frameworks/Python.framework/Versions/3.4/lib/python3.4/http/client.py", line 662, in _safe_read
    chunk = self.fp.read(min(amt, MAXAMOUNT))
  File "/Library/Frameworks/Python.framework/Versions/3.4/lib/python3.4/socket.py", line 371, in readinto
    return self._sock.recv_into(b)
KeyboardInterrupt
ERROR:root:Got exception on scrapAll
Traceback (most recent call last):
  File "ultimateCrawler.py", line 261, in scrapAll
    self.InsertLinkIds(title, artist, album, beat, melon, navermusic, youtube, bugs)
  File "ultimateCrawler.py", line 45, in InsertLinkIds
    self.cur.execute(query)
  File "/Library/Frameworks/Python.framework/Versions/3.4/lib/python3.4/site-packages/pymysql/cursors.py", line 135, in execute
    result = self._query(query)
  File "/Library/Frameworks/Python.framework/Versions/3.4/lib/python3.4/site-packages/pymysql/cursors.py", line 274, in _query
    conn.query(q)
  File "/Library/Frameworks/Python.framework/Versions/3.4/lib/python3.4/site-packages/pymysql/connections.py", line 712, in query
    sql = sql.encode(self.encoding)
UnicodeEncodeError: 'latin-1' codec can't encode characters in position 121-123: ordinal not in range(256)
DEBUG:root:Musicurie traceback log. It starts at
DEBUG:root:2015-02-13 00:43:20
ERROR:root:Got exception on scrapAll
Traceback (most recent call last):
  File "ultimateCrawler.py", line 261, in scrapAll
    self.InsertLinkIds(title, artist, album, beat, melon, navermusic, youtube, bugs)
  File "ultimateCrawler.py", line 45, in InsertLinkIds
    self.cur.execute(query)
  File "/Library/Frameworks/Python.framework/Versions/3.4/lib/python3.4/site-packages/pymysql/cursors.py", line 135, in execute
    result = self._query(query)
  File "/Library/Frameworks/Python.framework/Versions/3.4/lib/python3.4/site-packages/pymysql/cursors.py", line 274, in _query
    conn.query(q)
  File "/Library/Frameworks/Python.framework/Versions/3.4/lib/python3.4/site-packages/pymysql/connections.py", line 712, in query
    sql = sql.encode(self.encoding)
UnicodeEncodeError: 'latin-1' codec can't encode characters in position 121-123: ordinal not in range(256)
DEBUG:root:Musicurie traceback log. It starts at
DEBUG:root:2015-02-13 00:45:58
ERROR:root:Got exception on scrapAll
Traceback (most recent call last):
  File "ultimateCrawler.py", line 261, in scrapAll
    self.InsertLinkIds(title, artist, album, beat, melon, navermusic, youtube, bugs)
  File "ultimateCrawler.py", line 45, in InsertLinkIds
    self.cur.execute(query)
  File "/Library/Frameworks/Python.framework/Versions/3.4/lib/python3.4/site-packages/pymysql/cursors.py", line 135, in execute
    result = self._query(query)
  File "/Library/Frameworks/Python.framework/Versions/3.4/lib/python3.4/site-packages/pymysql/cursors.py", line 274, in _query
    conn.query(q)
  File "/Library/Frameworks/Python.framework/Versions/3.4/lib/python3.4/site-packages/pymysql/connections.py", line 712, in query
    sql = sql.encode(self.encoding)
UnicodeEncodeError: 'latin-1' codec can't encode characters in position 121-123: ordinal not in range(256)
