DEBUG:root:Musicurie traceback log. It starts at
DEBUG:root:2015-02-13 13:10:21
ERROR:root:Got exception on scrapNavermusic: 강희만-인생
Traceback (most recent call last):
  File "getTrackIDs.py", line 171, in scrapNavermusic
    contents=urlopen(modifiedURL, timeout=5)
  File "/Library/Frameworks/Python.framework/Versions/3.4/lib/python3.4/urllib/request.py", line 153, in urlopen
    return opener.open(url, data, timeout)
  File "/Library/Frameworks/Python.framework/Versions/3.4/lib/python3.4/urllib/request.py", line 455, in open
    response = self._open(req, data)
  File "/Library/Frameworks/Python.framework/Versions/3.4/lib/python3.4/urllib/request.py", line 473, in _open
    '_open', req)
  File "/Library/Frameworks/Python.framework/Versions/3.4/lib/python3.4/urllib/request.py", line 433, in _call_chain
    result = func(*args)
  File "/Library/Frameworks/Python.framework/Versions/3.4/lib/python3.4/urllib/request.py", line 1215, in http_open
    return self.do_open(http.client.HTTPConnection, req)
  File "/Library/Frameworks/Python.framework/Versions/3.4/lib/python3.4/urllib/request.py", line 1194, in do_open
    r = h.getresponse()
  File "/Library/Frameworks/Python.framework/Versions/3.4/lib/python3.4/http/client.py", line 1172, in getresponse
    response.begin()
  File "/Library/Frameworks/Python.framework/Versions/3.4/lib/python3.4/http/client.py", line 351, in begin
    version, status, reason = self._read_status()
  File "/Library/Frameworks/Python.framework/Versions/3.4/lib/python3.4/http/client.py", line 313, in _read_status
    line = str(self.fp.readline(_MAXLINE + 1), "iso-8859-1")
  File "/Library/Frameworks/Python.framework/Versions/3.4/lib/python3.4/socket.py", line 371, in readinto
    return self._sock.recv_into(b)
socket.timeout: timed out
DEBUG:root:Musicurie traceback log. It starts at
DEBUG:root:2015-02-13 13:13:15
ERROR:root:Got exception on scrapAll
Traceback (most recent call last):
  File "getTrackIDs.py", line 268, in scrapFrom
    self.InsertLinkIds(title, artist, album, trackId, appID)
  File "getTrackIDs.py", line 67, in InsertLinkIds
    self.cur.execute(query)
  File "/Library/Frameworks/Python.framework/Versions/3.4/lib/python3.4/site-packages/pymysql/cursors.py", line 135, in execute
    result = self._query(query)
  File "/Library/Frameworks/Python.framework/Versions/3.4/lib/python3.4/site-packages/pymysql/cursors.py", line 274, in _query
    conn.query(q)
  File "/Library/Frameworks/Python.framework/Versions/3.4/lib/python3.4/site-packages/pymysql/connections.py", line 714, in query
    self._affected_rows = self._read_query_result(unbuffered=unbuffered)
  File "/Library/Frameworks/Python.framework/Versions/3.4/lib/python3.4/site-packages/pymysql/connections.py", line 865, in _read_query_result
    result.read()
  File "/Library/Frameworks/Python.framework/Versions/3.4/lib/python3.4/site-packages/pymysql/connections.py", line 1062, in read
    first_packet = self.connection._read_packet()
  File "/Library/Frameworks/Python.framework/Versions/3.4/lib/python3.4/site-packages/pymysql/connections.py", line 830, in _read_packet
    packet.check_error()
  File "/Library/Frameworks/Python.framework/Versions/3.4/lib/python3.4/site-packages/pymysql/connections.py", line 348, in check_error
    raise_mysql_exception(self._data)
  File "/Library/Frameworks/Python.framework/Versions/3.4/lib/python3.4/site-packages/pymysql/err.py", line 116, in raise_mysql_exception
    _check_mysql_exception(errinfo)
  File "/Library/Frameworks/Python.framework/Versions/3.4/lib/python3.4/site-packages/pymysql/err.py", line 109, in _check_mysql_exception
    raise errorclass(errno,errorvalue)
pymysql.err.IntegrityError: (1062, "Duplicate entry '129-4-441985' for key 'idx_link_ids_song_id_app_id_link_id'")
DEBUG:root:Musicurie traceback log. It starts at
DEBUG:root:2015-02-13 13:15:08
ERROR:root:(1062, "Duplicate entry '129-4-441985' for key 'idx_link_ids_song_id_app_id_link_id'")
Traceback (most recent call last):
  File "getTrackIDs.py", line 67, in InsertLinkIds
    self.cur.execute(query)
  File "/Library/Frameworks/Python.framework/Versions/3.4/lib/python3.4/site-packages/pymysql/cursors.py", line 135, in execute
    result = self._query(query)
  File "/Library/Frameworks/Python.framework/Versions/3.4/lib/python3.4/site-packages/pymysql/cursors.py", line 274, in _query
    conn.query(q)
  File "/Library/Frameworks/Python.framework/Versions/3.4/lib/python3.4/site-packages/pymysql/connections.py", line 714, in query
    self._affected_rows = self._read_query_result(unbuffered=unbuffered)
  File "/Library/Frameworks/Python.framework/Versions/3.4/lib/python3.4/site-packages/pymysql/connections.py", line 865, in _read_query_result
    result.read()
  File "/Library/Frameworks/Python.framework/Versions/3.4/lib/python3.4/site-packages/pymysql/connections.py", line 1062, in read
    first_packet = self.connection._read_packet()
  File "/Library/Frameworks/Python.framework/Versions/3.4/lib/python3.4/site-packages/pymysql/connections.py", line 830, in _read_packet
    packet.check_error()
  File "/Library/Frameworks/Python.framework/Versions/3.4/lib/python3.4/site-packages/pymysql/connections.py", line 348, in check_error
    raise_mysql_exception(self._data)
  File "/Library/Frameworks/Python.framework/Versions/3.4/lib/python3.4/site-packages/pymysql/err.py", line 116, in raise_mysql_exception
    _check_mysql_exception(errinfo)
  File "/Library/Frameworks/Python.framework/Versions/3.4/lib/python3.4/site-packages/pymysql/err.py", line 109, in _check_mysql_exception
    raise errorclass(errno,errorvalue)
pymysql.err.IntegrityError: (1062, "Duplicate entry '129-4-441985' for key 'idx_link_ids_song_id_app_id_link_id'")
ERROR:root:(1062, "Duplicate entry '129-4-441985' for key 'idx_link_ids_song_id_app_id_link_id'")
Traceback (most recent call last):
  File "getTrackIDs.py", line 67, in InsertLinkIds
    self.cur.execute(query)
  File "/Library/Frameworks/Python.framework/Versions/3.4/lib/python3.4/site-packages/pymysql/cursors.py", line 135, in execute
    result = self._query(query)
  File "/Library/Frameworks/Python.framework/Versions/3.4/lib/python3.4/site-packages/pymysql/cursors.py", line 274, in _query
    conn.query(q)
  File "/Library/Frameworks/Python.framework/Versions/3.4/lib/python3.4/site-packages/pymysql/connections.py", line 714, in query
    self._affected_rows = self._read_query_result(unbuffered=unbuffered)
  File "/Library/Frameworks/Python.framework/Versions/3.4/lib/python3.4/site-packages/pymysql/connections.py", line 865, in _read_query_result
    result.read()
  File "/Library/Frameworks/Python.framework/Versions/3.4/lib/python3.4/site-packages/pymysql/connections.py", line 1062, in read
    first_packet = self.connection._read_packet()
  File "/Library/Frameworks/Python.framework/Versions/3.4/lib/python3.4/site-packages/pymysql/connections.py", line 830, in _read_packet
    packet.check_error()
  File "/Library/Frameworks/Python.framework/Versions/3.4/lib/python3.4/site-packages/pymysql/connections.py", line 348, in check_error
    raise_mysql_exception(self._data)
  File "/Library/Frameworks/Python.framework/Versions/3.4/lib/python3.4/site-packages/pymysql/err.py", line 116, in raise_mysql_exception
    _check_mysql_exception(errinfo)
  File "/Library/Frameworks/Python.framework/Versions/3.4/lib/python3.4/site-packages/pymysql/err.py", line 109, in _check_mysql_exception
    raise errorclass(errno,errorvalue)
pymysql.err.IntegrityError: (1062, "Duplicate entry '129-4-441985' for key 'idx_link_ids_song_id_app_id_link_id'")
ERROR:root:(1062, "Duplicate entry '129-4-441985' for key 'idx_link_ids_song_id_app_id_link_id'")
Traceback (most recent call last):
  File "getTrackIDs.py", line 67, in InsertLinkIds
    self.cur.execute(query)
  File "/Library/Frameworks/Python.framework/Versions/3.4/lib/python3.4/site-packages/pymysql/cursors.py", line 135, in execute
    result = self._query(query)
  File "/Library/Frameworks/Python.framework/Versions/3.4/lib/python3.4/site-packages/pymysql/cursors.py", line 274, in _query
    conn.query(q)
  File "/Library/Frameworks/Python.framework/Versions/3.4/lib/python3.4/site-packages/pymysql/connections.py", line 714, in query
    self._affected_rows = self._read_query_result(unbuffered=unbuffered)
  File "/Library/Frameworks/Python.framework/Versions/3.4/lib/python3.4/site-packages/pymysql/connections.py", line 865, in _read_query_result
    result.read()
  File "/Library/Frameworks/Python.framework/Versions/3.4/lib/python3.4/site-packages/pymysql/connections.py", line 1062, in read
    first_packet = self.connection._read_packet()
  File "/Library/Frameworks/Python.framework/Versions/3.4/lib/python3.4/site-packages/pymysql/connections.py", line 830, in _read_packet
    packet.check_error()
  File "/Library/Frameworks/Python.framework/Versions/3.4/lib/python3.4/site-packages/pymysql/connections.py", line 348, in check_error
    raise_mysql_exception(self._data)
  File "/Library/Frameworks/Python.framework/Versions/3.4/lib/python3.4/site-packages/pymysql/err.py", line 116, in raise_mysql_exception
    _check_mysql_exception(errinfo)
  File "/Library/Frameworks/Python.framework/Versions/3.4/lib/python3.4/site-packages/pymysql/err.py", line 109, in _check_mysql_exception
    raise errorclass(errno,errorvalue)
pymysql.err.IntegrityError: (1062, "Duplicate entry '129-4-441985' for key 'idx_link_ids_song_id_app_id_link_id'")
DEBUG:root:Musicurie traceback log. It starts at
DEBUG:root:2015-02-13 13:20:59
ERROR:root:'Crawler' object has no attribute 'cur'
Traceback (most recent call last):
  File "getTrackIDs.py", line 68, in InsertLinkIds
    self.cur.execute(query)
AttributeError: 'Crawler' object has no attribute 'cur'
ERROR:root:'Crawler' object has no attribute 'cur'
Traceback (most recent call last):
  File "getTrackIDs.py", line 68, in InsertLinkIds
    self.cur.execute(query)
AttributeError: 'Crawler' object has no attribute 'cur'
ERROR:root:'Crawler' object has no attribute 'cur'
Traceback (most recent call last):
  File "getTrackIDs.py", line 68, in InsertLinkIds
    self.cur.execute(query)
AttributeError: 'Crawler' object has no attribute 'cur'
ERROR:root:'Crawler' object has no attribute 'cur'
Traceback (most recent call last):
  File "getTrackIDs.py", line 68, in InsertLinkIds
    self.cur.execute(query)
AttributeError: 'Crawler' object has no attribute 'cur'
DEBUG:root:Musicurie traceback log. It starts at
DEBUG:root:2015-02-13 13:30:57
ERROR:root:'Crawler' object has no attribute 'cur'
Traceback (most recent call last):
  File "getTrackIDs.py", line 68, in InsertLinkIds
    self.cur.execute(query)
AttributeError: 'Crawler' object has no attribute 'cur'
ERROR:root:'Crawler' object has no attribute 'cur'
Traceback (most recent call last):
  File "getTrackIDs.py", line 68, in InsertLinkIds
    self.cur.execute(query)
AttributeError: 'Crawler' object has no attribute 'cur'
ERROR:root:'Crawler' object has no attribute 'cur'
Traceback (most recent call last):
  File "getTrackIDs.py", line 68, in InsertLinkIds
    self.cur.execute(query)
AttributeError: 'Crawler' object has no attribute 'cur'
DEBUG:root:Musicurie traceback log. It starts at
DEBUG:root:2015-02-13 13:31:21
ERROR:root:'Crawler' object has no attribute 'cur'
Traceback (most recent call last):
  File "getTrackIDs.py", line 68, in InsertLinkIds
    self.cur.execute(query)
AttributeError: 'Crawler' object has no attribute 'cur'
ERROR:root:'Crawler' object has no attribute 'cur'
Traceback (most recent call last):
  File "getTrackIDs.py", line 68, in InsertLinkIds
    self.cur.execute(query)
AttributeError: 'Crawler' object has no attribute 'cur'
ERROR:root:'Crawler' object has no attribute 'cur'
Traceback (most recent call last):
  File "getTrackIDs.py", line 68, in InsertLinkIds
    self.cur.execute(query)
AttributeError: 'Crawler' object has no attribute 'cur'
DEBUG:root:Musicurie traceback log. It starts at
DEBUG:root:2015-02-13 13:31:36
ERROR:root:'Crawler' object has no attribute 'cur'
Traceback (most recent call last):
  File "getTrackIDs.py", line 68, in InsertLinkIds
    self.cur.execute(query)
AttributeError: 'Crawler' object has no attribute 'cur'
ERROR:root:'Crawler' object has no attribute 'cur'
Traceback (most recent call last):
  File "getTrackIDs.py", line 68, in InsertLinkIds
    self.cur.execute(query)
AttributeError: 'Crawler' object has no attribute 'cur'
ERROR:root:'Crawler' object has no attribute 'cur'
Traceback (most recent call last):
  File "getTrackIDs.py", line 68, in InsertLinkIds
    self.cur.execute(query)
AttributeError: 'Crawler' object has no attribute 'cur'
